tests/64_threads/sample_92.in
64
o
56 S 101 5 120 337
61 B 103 2 152 780
61 B 104 9 110 563
17 S 105 5 195 603
16 S 106 6 192 389
62 S 107 8 101 80
61 C 103
44 B 110 2 167 14
21 S 112 2 101 118
10 B 114 6 192 953
50 B 115 4 125 816
58 S 116 7 147 333
62 B 118 2 150 719
52 S 119 9 111 221
18 S 122 8 104 76
14 B 123 9 119 340
19 S 126 4 117 569
22 S 127 6 190 994
60 B 128 8 131 303
19 C 126
45 B 131 8 136 381
40 S 132 3 146 968
49 S 133 7 147 129
41 S 134 8 173 994
40 C 132
32 B 136 7 186 888
41 S 138 9 143 904
33 B 140 1 172 351
50 B 141 0 155 655
30 S 142 2 172 49
13 B 145 4 136 573
13 C 145
18 C 122
21 S 148 0 138 105
39 B 149 8 194 995
22 B 150 7 141 36
39 C 149
1 B 154 4 105 146
16 B 155 3 191 284
13 B 157 7 116 762
14 B 158 1 157 788
9 B 159 9 101 729
23 S 160 2 185 345
12 S 161 5 180 336
37 S 162 4 114 555
20 S 164 5 143 587
50 C 141
13 B 168 7 193 40
52 C 119
33 C 140
52 C 119
32 B 172 8 196 489
59 S 173 9 148 310
8 S 175 1 125 220
60 C 128
59 B 177 0 197 111
43 S 178 6 159 267
45 B 179 8 101 297
59 S 180 5 109 571
1 S 182 0 120 516
39 S 183 8 117 650
43 S 184 4 100 448
24 B 185 6 196 406
45 B 186 0 191 33
34 B 187 4 138 770
52 B 188 6 197 226
21 B 189 9 154 617
40 S 190 7 155 259
45 B 191 3 183 196
36 B 192 9 147 35
38 B 193 7 123 567
1 S 194 6 153 515
11 B 197 3 182 599
61 B 198 7 174 465
58 C 116
8 B 200 8 152 370
8 C 200
10 S 203 5 181 521
13 C 157
46 B 205 2 167 41
9 S 206 3 183 398
62 C 118
20 B 209 7 133 357
12 B 210 4 194 912
13 S 211 6 137 256
31 B 212 4 131 453
57 B 214 8 155 235
45 B 215 5 132 829
37 B 217 9 116 279
4 S 218 8 132 644
28 S 219 1 149 405
22 B 220 8 180 200
25 B 221 3 109 263
39 B 222 9 155 784
34 B 223 2 103 82
1 C 182
40 C 132
3 S 226 0 100 189
37 C 217
35 S 228 8 148 555
32 S 229 9 199 722
39 C 222
25 B 231 0 180 788
56 B 232 7 187 512
58 S 233 3 143 151
60 B 235 7 170 507
16 C 155
38 B 238 3 179 611
46 B 239 9 160 669
36 C 192
60 B 241 7 146 566
55 S 242 5 112 518
4 S 243 0 116 409
49 C 133
49 S 245 0 186 953
19 B 246 2 182 429
26 B 247 6 163 602
35 B 248 8 129 237
34 B 249 7 183 335
9 B 250 0 104 979
8 C 200
3 C 226
55 S 253 5 138 364
2 B 254 2 159 305
6 S 255 8 189 880
45 C 179
8 S 257 9 149 328
44 B 258 6 169 666
3 S 259 6 121 741
9 B 261 3 163 521
55 B 262 9 118 855
26 B 263 7 144 478
57 B 264 5 165 807
5 B 265 3 131 991
1 S 266 1 101 800
43 C 184
19 C 126
61 B 269 9 120 63
4 C 243
60 B 271 1 115 444
47 S 272 8 183 862
25 B 273 4 113 410
63 B 274 2 126 525
25 C 231
20 C 164
8 B 277 0 143 743
50 S 278 2 122 792
5 C 265
36 B 280 7 151 71
29 S 281 6 129 806
20 B 282 1 133 168
56 S 283 8 199 819
5 C 265
23 S 286 1 148 34
41 C 138
4 B 288 4 172 666
23 B 289 2 135 136
27 S 290 0 175 64
24 B 291 0 150 201
38 C 238
5 C 265
39 B 295 3 102 37
49 B 296 2 110 769
14 C 123
49 C 133
13 S 299 9 144 638
33 S 300 9 171 740
19 S 301 0 141 556
36 C 280
39 C 183
40 B 304 4 183 246
32 C 172
34 B 306 5 180 254
7 B 307 8 197 32
12 C 161
2 C 254
22 S 310 1 112 812
49 C 133
27 B 312 9 109 491
20 S 313 6 146 359
46 B 314 5 159 402
47 B 315 6 197 670
60 B 316 4 114 134
12 B 317 8 140 483
40 B 318 6 115 768
28 S 319 2 130 195
5 S 320 3 186 674
0 B 321 1 200 415
18 S 322 0 187 797
44 B 323 0 136 879
53 S 324 8 180 681
25 S 325 3 132 326
53 S 326 6 149 797
37 B 327 8 165 866
43 C 178
14 B 329 5 178 218
60 C 241
50 S 331 6 194 930
50 C 141
59 C 177
49 B 334 2 178 742
41 B 335 1 126 815
11 B 336 0 197 906
4 B 337 9 120 860
0 C 321
16 B 339 0 130 270
56 C 283
23 C 286
10 C 114
10 B 344 5 172 167
6 S 345 8 183 705
58 C 116
48 B 348 4 155 78
57 S 349 7 130 493
48 C 348
4 B 351 8 108 504
16 C 339
0 C 321
13 S 354 9 118 292
39 S 355 5 193 998
14 B 356 5 142 660
61 C 198
48 C 348
33 C 140
9 S 360 6 103 266
16 C 155
42 S 362 9 152 588
29 C 281
59 S 364 5 173 78
12 S 365 6 122 585
9 B 366 1 156 330
62 C 107
25 C 273
37 C 217
50 S 370 2 115 952
59 S 371 9 169 678
9 B 372 8 136 228
46 B 373 3 160 12
61 S 374 4 129 111
57 B 375 3 127 644
0 B 377 0 109 748
5 S 378 3 130 194
23 B 379 9 173 786
35 C 228
48 C 348
60 C 241
63 C 274
2 S 384 9 185 847
41 C 138
28 B 386 4 106 180
8 C 277
35 B 388 5 143 620
15 S 389 2 197 583
49 C 133
36 S 391 5 125 147
62 B 392 6 140 276
1 C 194
43 C 178
39 C 183
63 S 396 0 113 201
60 C 271
41 B 398 4 162 823
9 C 250
5 C 320
48 S 402 9 157 336
57 B 403 7 111 992
26 S 404 8 145 614
4 S 405 1 181 907
62 B 406 3 119 777
0 C 377
40 C 190
21 S 409 4 105 254
13 S 410 0 108 902
61 B 411 9 121 28
30 C 142
18 B 413 1 117 910
59 S 414 9 135 566
32 C 136
34 B 416 5 136 776
59 B 417 1 158 243
42 S 418 3 150 538
46 C 239
49 B 420 9 180 553
9 B 421 7 139 766
1 S 422 1 151 492
22 S 423 2 171 220
15 C 389
36 B 425 5 186 302
5 S 426 0 139 185
48 S 427 6 120 979
33 S 428 5 156 529
46 S 429 3 145 742
7 B 430 5 200 682
15 S 431 4 178 312
63 C 274
26 B 433 4 108 17
47 C 315
53 S 435 8 169 91
10 B 436 9 121 464
16 B 437 3 110 855
31 S 438 8 144 31
7 B 439 1 101 739
0 S 440 7 159 891
2 B 441 8 177 240
33 S 442 6 144 291
2 C 254
5 C 265
50 C 278
10 B 446 5 114 895
12 C 161
4 C 351
7 B 449 5 161 67
20 S 450 6 134 280
16 B 451 6 171 604
38 B 452 8 113 929
31 B 453 3 169 715
0 S 454 1 124 583
44 C 323
62 S 456 5 196 891
13 B 457 8 105 626
63 C 274
19 B 459 3 178 229
58 S 460 5 101 10
20 C 164
29 B 462 4 119 292
43 C 178
27 C 290
19 S 465 1 180 90
39 B 466 2 182 426
38 B 467 9 113 118
0 B 468 5 125 506
38 S 469 9 111 210
62 C 456
56 S 471 9 119 380
7 C 449
3 S 473 2 176 116
53 C 435
36 B 475 7 190 486
28 B 476 0 110 427
53 S 477 0 196 164
39 B 478 3 113 873
18 S 479 1 152 574
59 B 480 5 173 853
41 C 335
46 C 429
27 C 312
49 C 133
13 C 410
33 S 486 8 140 368
21 S 487 5 182 482
9 S 488 4 126 264
26 C 404
5 S 490 5 145 811
4 S 491 2 128 703
52 B 492 3 103 344
30 S 493 1 181 788
45 C 179
2 B 495 2 179 945
25 S 496 3 135 419
58 B 497 9 179 805
42 B 498 3 154 771
45 S 499 7 187 658
51 S 500 1 103 343
46 C 314
45 C 186
3 B 503 1 120 493
56 B 504 2 148 280
53 S 505 0 118 418
13 S 506 7 186 325
1 C 194
18 B 508 0 138 777
13 B 509 5 136 621
22 C 127
20 S 511 2 112 515
28 C 386
26 C 263
0 S 514 6 125 722
7 S 515 6 188 81
55 B 516 7 109 613
57 S 517 8 171 667
37 C 217
60 S 519 6 107 904
54 S 520 5 100 831
49 C 133
59 C 480
3 C 259
27 S 524 5 157 294
60 B 525 4 109 696
26 C 263
59 B 527 1 135 983
6 B 528 9 188 290
8 S 529 8 156 353
50 S 530 6 115 672
7 S 531 2 129 652
13 C 157
60 S 533 5 128 914
27 C 312
7 S 535 1 165 938
39 C 183
29 S 537 6 131 571
11 B 538 9 193 625
39 C 183
0 C 440
0 B 541 1 128 930
22 S 542 2 137 219
2 S 543 3 178 288
50 B 544 3 120 535
53 C 435
59 C 180
47 C 315
30 B 548 3 127 511
25 S 549 7 130 267
46 C 205
44 C 110
6 S 552 9 122 238
36 C 425
45 S 554 8 109 523
15 B 555 3 191 857
55 C 262
61 S 557 3 141 397
45 S 558 8 116 669
41 S 559 3 160 264
26 S 560 5 139 718
13 S 561 0 100 688
28 S 562 1 112 594
56 B 563 4 103 646
38 C 238
0 S 565 8 145 86
62 B 566 0 193 483
15 B 567 4 109 722
63 B 568 9 195 479
38 B 569 7 182 700
40 C 318
60 B 571 9 177 219
24 B 572 4 115 998
7 C 307
3 B 574 6 103 297
20 S 575 6 133 765
53 S 576 5 141 481
49 B 577 6 133 995
38 S 578 0 127 179
38 S 579 2 192 386
29 C 462
48 S 581 1 177 783
42 S 582 4 149 684
42 S 583 2 155 71
22 S 584 1 197 186
47 C 272
60 C 571
17 S 587 9 122 893
11 B 588 0 123 21
48 S 589 3 148 865
58 B 590 0 117 487
31 S 591 6 200 685
41 C 138
52 B 593 1 177 276
42 B 594 0 187 921
27 S 595 9 130 927
17 S 596 2 101 63
2 C 384
47 C 315
41 C 559
19 S 600 8 138 723
41 S 601 1 175 770
11 S 602 0 114 131
0 C 454
18 C 122
49 B 605 3 148 265
23 S 606 8 120 647
53 B 607 2 168 934
25 B 608 1 161 905
31 S 609 3 193 680
36 C 391
32 S 611 3 149 602
35 C 248
60 B 613 2 107 183
13 S 614 7 105 179
10 B 615 8 104 551
27 B 616 3 124 52
60 S 617 3 127 504
44 B 618 7 192 512
45 B 619 8 109 439
40 B 620 3 100 272
26 C 560
25 B 622 4 169 473
56 B 623 2 162 345
63 S 624 2 114 998
5 S 625 9 107 646
44 C 618
6 S 627 2 183 523
4 S 628 7 147 729
55 B 629 8 181 53
21 B 630 7 163 883
39 B 631 3 166 531
27 C 616
17 S 633 5 140 546
10 C 436
16 B 635 8 146 545
56 S 636 4 119 515
16 C 437
32 S 638 2 182 217
53 B 639 8 177 332
57 C 264
37 S 641 7 109 356
30 B 642 9 127 680
