tests/64_threads/sample_93.in
64
o
31 S 102 8 129 321
57 B 103 3 127 390
18 S 104 4 148 266
34 S 106 3 178 79
15 B 107 0 116 902
6 B 108 9 181 900
30 S 109 1 164 786
56 S 110 8 116 330
40 B 111 1 162 218
52 S 112 7 137 886
57 S 113 9 126 477
11 S 114 2 113 619
27 S 115 6 186 813
22 S 116 7 179 891
16 S 119 3 109 314
55 S 120 8 183 742
27 C 115
61 B 124 7 127 743
18 S 125 1 191 182
63 B 127 5 137 548
33 B 129 6 178 412
11 C 114
54 S 131 8 177 518
43 S 133 3 187 328
60 S 134 7 161 585
52 B 135 5 122 333
54 C 131
42 B 137 6 195 826
23 S 138 9 185 589
47 S 139 7 124 582
52 B 140 6 122 944
31 S 141 5 170 520
61 S 142 1 137 703
24 S 143 2 103 552
50 B 144 0 135 42
5 S 145 7 121 660
2 B 146 2 157 189
51 S 147 5 117 607
26 B 149 9 168 371
42 C 137
34 S 151 1 105 515
34 B 152 0 169 119
18 B 153 2 118 693
34 C 152
0 B 155 5 165 981
10 B 156 0 130 13
41 S 157 0 186 562
46 B 158 5 169 529
63 C 127
57 B 160 4 155 862
1 B 161 7 136 238
52 C 135
24 B 163 1 190 361
60 S 164 0 160 835
57 S 166 5 106 25
54 S 167 4 126 144
12 B 168 6 175 184
63 S 169 8 170 309
63 S 170 5 145 251
35 S 171 3 119 370
26 C 149
63 S 173 2 109 564
63 B 174 5 129 517
30 S 175 0 175 701
47 C 139
38 S 177 7 134 274
42 B 178 4 164 332
57 C 160
60 C 164
43 C 133
26 C 149
57 S 184 0 160 834
4 S 185 0 166 151
19 S 186 6 163 775
26 S 187 7 126 515
47 C 139
61 C 142
50 S 190 0 187 632
37 S 191 4 164 412
11 B 192 1 178 738
15 S 193 3 129 332
59 B 194 4 194 122
58 B 195 9 110 706
17 B 197 3 128 317
33 C 129
27 B 199 6 200 371
51 B 200 6 114 590
44 B 201 5 111 779
63 B 202 6 185 787
47 S 203 4 138 138
16 S 204 5 175 23
41 S 205 0 143 258
51 S 206 8 190 454
12 B 207 1 174 582
6 B 208 9 146 906
24 C 143
6 S 211 0 165 603
30 S 212 9 144 134
1 S 213 8 144 671
32 S 214 9 184 484
47 B 215 9 113 553
50 C 144
62 S 217 4 112 761
26 S 218 3 186 222
33 C 129
5 B 220 4 173 645
11 S 221 8 121 625
25 S 222 1 183 356
23 C 138
32 B 224 2 175 941
16 C 119
14 S 226 5 121 881
30 C 212
3 S 230 1 154 637
5 B 231 6 191 292
13 B 232 9 110 553
12 B 233 5 123 693
2 S 234 6 155 125
57 C 113
41 C 157
8 S 237 0 126 498
31 C 141
16 C 119
47 B 240 0 180 328
26 B 241 9 141 223
55 C 120
56 S 243 6 163 301
6 C 208
29 S 245 8 200 94
50 B 246 0 186 836
54 B 247 9 106 838
15 C 193
11 B 249 5 152 329
47 S 250 7 151 827
15 B 251 4 170 701
13 C 232
41 C 157
39 S 254 9 147 440
50 B 255 3 181 15
17 B 256 0 146 950
38 C 177
13 S 258 5 197 390
6 S 259 6 150 577
2 C 146
63 B 261 1 176 753
37 B 262 3 138 513
31 C 141
18 S 264 2 126 880
18 S 265 5 103 665
38 C 177
60 C 164
36 B 268 5 189 124
17 C 197
34 S 270 2 139 114
28 S 271 8 162 583
40 S 272 1 181 779
27 B 273 3 151 273
44 B 274 5 132 510
17 B 275 3 175 678
27 C 199
59 C 194
56 B 278 6 153 759
2 S 279 4 144 285
48 S 280 2 106 960
29 C 245
33 S 284 4 182 516
59 C 194
3 C 230
43 B 287 9 102 443
36 S 288 3 176 81
56 C 110
10 B 290 0 136 980
47 C 139
49 S 292 4 185 320
51 B 293 8 143 834
36 C 288
2 S 295 7 112 513
61 B 296 6 157 442
31 C 102
49 S 298 2 111 357
60 C 134
2 B 300 8 107 528
24 S 301 7 173 748
39 B 302 7 124 204
15 S 303 8 100 358
39 B 304 9 130 283
63 B 305 8 168 700
39 C 304
53 B 307 0 143 279
19 C 186
3 C 230
35 S 310 5 132 461
36 S 311 5 171 221
49 S 313 1 198 601
56 S 314 9 131 354
38 C 177
48 S 316 7 114 681
0 C 155
46 B 318 3 156 192
54 S 319 7 184 555
10 B 320 0 175 266
41 C 205
54 B 322 8 132 165
8 C 237
11 B 324 5 118 337
28 C 271
38 C 177
17 B 327 9 144 243
41 S 328 6 129 808
28 B 329 7 131 573
2 S 330 0 116 949
16 S 331 2 132 985
27 C 273
8 B 333 4 136 151
63 B 334 5 144 634
21 B 335 0 155 757
22 C 116
10 C 156
47 C 139
17 C 197
39 B 340 3 166 898
23 B 341 0 136 358
10 B 342 8 152 714
15 C 193
39 S 344 9 136 410
44 B 345 4 198 76
34 S 346 2 170 963
22 B 347 0 115 344
46 C 158
57 S 349 7 154 346
20 S 350 3 177 780
53 C 307
63 B 352 4 189 842
46 B 353 6 186 62
33 C 284
21 B 355 1 112 793
1 B 356 2 120 977
45 S 357 6 127 218
63 B 358 2 146 272
16 B 359 8 122 218
40 S 360 0 115 116
12 S 361 1 117 593
14 B 362 0 107 203
38 B 363 0 172 762
1 B 365 0 144 348
17 B 366 5 138 135
19 B 367 9 175 797
27 B 368 0 182 22
40 B 369 1 164 343
39 B 370 1 191 854
11 C 192
62 S 372 2 179 407
11 C 192
36 S 374 2 151 688
20 C 350
39 S 376 2 118 66
18 C 264
23 C 341
25 B 379 3 166 392
37 B 380 7 191 399
26 C 218
18 B 382 3 130 580
34 B 383 2 110 430
0 S 384 1 101 362
12 B 385 3 172 239
34 B 386 4 123 824
12 S 387 1 178 754
57 S 388 1 140 694
34 S 389 4 144 805
32 C 214
16 S 391 6 169 732
12 S 392 8 133 515
38 S 393 0 159 751
31 B 394 5 126 31
36 B 395 6 114 137
21 S 396 1 200 865
19 C 367
33 C 129
17 B 399 2 170 748
43 B 400 3 150 784
53 C 307
24 C 143
52 C 112
47 S 404 6 188 798
46 C 353
27 B 406 2 149 655
19 S 407 2 132 97
42 S 408 5 184 464
62 C 372
38 S 410 2 156 267
7 S 411 9 126 338
24 B 412 2 151 760
2 B 413 7 187 412
16 S 414 1 185 580
40 S 415 1 120 737
37 B 416 5 138 703
51 B 417 0 124 963
45 S 418 4 109 350
49 C 292
4 S 420 5 138 681
52 C 112
45 B 422 0 145 118
50 S 423 6 158 99
39 B 424 0 150 42
16 S 425 6 111 381
6 B 426 1 138 500
54 S 427 3 169 509
18 C 382
38 C 363
26 C 149
2 C 234
1 C 365
45 S 433 3 125 616
34 S 434 6 170 526
38 S 435 7 200 757
26 C 241
11 S 437 0 171 248
38 B 438 1 170 774
35 S 439 8 159 272
33 S 440 8 160 631
52 S 441 8 122 44
3 C 230
19 S 443 4 176 23
47 C 215
41 S 445 8 135 474
31 S 446 6 111 888
7 C 411
2 B 448 4 156 850
57 S 449 4 177 387
41 C 205
44 S 451 7 173 98
12 C 233
54 B 453 0 158 10
14 C 362
44 C 451
1 C 161
62 B 457 1 161 201
15 S 458 4 131 898
15 C 303
33 C 129
44 C 274
26 S 462 1 139 602
57 S 463 2 181 1000
52 S 464 0 107 875
55 B 465 8 179 213
42 C 178
27 B 467 3 162 353
23 B 468 2 119 290
51 B 469 3 125 789
48 B 470 8 200 278
47 C 404
61 S 472 4 149 257
3 S 473 0 129 983
60 B 474 6 151 434
7 S 475 4 160 471
39 C 370
22 B 477 1 118 588
27 C 273
32 S 479 4 105 471
6 S 480 5 141 143
47 B 481 1 121 207
52 S 482 5 122 428
23 S 483 4 190 212
44 B 484 6 100 678
35 B 485 0 160 35
14 B 486 9 166 610
63 S 487 8 200 693
22 C 347
40 S 489 3 175 964
34 B 490 9 170 734
61 C 296
33 C 129
46 C 158
31 C 141
15 C 458
20 S 496 8 159 313
6 B 497 2 148 225
21 S 498 2 141 596
32 C 224
40 S 500 1 183 927
37 B 501 8 105 37
63 B 502 7 165 725
21 S 503 7 159 292
36 S 504 3 106 348
5 C 220
18 C 382
39 C 304
53 C 307
24 C 163
9 S 510 4 101 1000
29 B 511 4 197 570
32 B 512 3 119 442
59 C 194
22 C 477
58 S 515 1 114 840
63 C 261
38 B 517 0 193 357
43 C 133
22 C 116
62 C 457
43 C 287
9 S 522 5 152 899
51 B 523 6 164 569
37 B 524 3 199 154
25 C 222
49 S 526 0 121 530
8 C 333
36 C 268
0 S 529 1 109 885
22 S 530 1 138 62
6 B 531 2 122 632
61 C 296
3 C 230
19 B 534 3 198 563
61 B 535 4 148 385
13 S 536 5 171 597
58 B 537 3 141 720
1 S 538 0 119 806
17 S 539 7 171 953
19 S 540 5 136 380
6 S 541 8 130 596
52 C 135
6 B 543 0 198 794
30 S 544 0 121 445
25 C 379
16 C 331
24 S 547 2 177 238
48 C 316
25 B 549 1 194 526
34 B 550 1 162 255
51 C 147
11 B 552 9 151 432
20 S 553 7 176 287
63 S 554 1 159 282
47 C 139
14 B 556 1 165 158
50 B 557 8 176 678
9 B 558 4 151 190
16 C 425
32 C 214
26 S 561 1 117 301
48 B 562 0 164 84
43 S 563 0 143 177
22 C 116
49 B 565 0 162 292
0 S 566 5 180 106
48 B 567 0 165 952
12 C 385
61 C 142
17 B 570 9 199 189
32 S 571 0 158 616
30 B 572 3 133 698
8 B 573 3 134 329
38 B 574 1 113 620
46 C 353
49 S 576 9 170 842
33 S 577 6 139 101
59 S 578 1 187 550
5 S 579 0 172 711
32 B 580 2 155 868
35 B 581 4 182 747
40 C 489
62 S 583 0 155 140
24 S 584 7 130 95
43 B 585 2 198 882
51 B 586 2 199 380
13 S 587 8 200 724
38 S 588 5 153 952
59 B 589 5 188 946
32 C 580
35 S 591 8 137 54
43 S 592 0 123 625
62 B 593 6 113 430
49 S 594 2 109 104
21 S 595 8 195 983
14 B 596 0 130 40
37 C 501
59 S 598 5 119 876
8 C 237
29 B 600 7 166 916
61 S 601 2 178 965
13 S 602 9 200 842
27 S 603 2 187 906
42 C 408
0 S 605 6 150 752
22 B 606 3 147 502
6 S 607 3 115 736
30 S 608 9 124 712
39 B 609 5 172 766
63 B 610 5 167 978
53 B 611 2 134 151
17 B 612 6 141 907
10 B 613 8 196 472
38 C 177
0 B 615 9 176 849
11 S 616 7 183 879
52 B 617 1 107 982
37 C 524
11 S 619 0 112 39
2 C 448
23 C 341
37 S 622 3 146 927
50 B 623 4 120 474
